Workbook

Sheet Phân công
A1: Mã | B1: Task | C1: Cặp | D1: FE phụ trách | E1: BE phụ trách | F1: Sprint | G1: Bắt đầu | H1: Kết thúc | I1: Priority | J1: Chức năng (FR Tai_Lieu) | K1: Issue | L1: Trạng thái
A2: C-01 | B2: Nền tảng FE: design tokens, Master layout & routing | C2: Chung | D2: =IFERROR(INDEX('Thành viên'!$B$2:$B$4,MATCH(C2,'Thành viên'!$A$2:$A$4,0))&"","") | E2: =IFERROR(INDEX('Thành viên'!$C$2:$C$4,MATCH(C2,'Thành viên'!$A$2:$A$4,0))&"","") | F2: Sprint 1 | G2: 46293 | H2: 46299 | I2: P0 Critical | J2: Nền tảng FE | K2: #31 | L2: Todo
A3: P1-01 | B3: Đăng nhập, JWT & điều hướng 5 vai trò | C3: Cặp 1 | D3: =IFERROR(INDEX('Thành viên'!$B$2:$B$4,MATCH(C3,'Thành viên'!$A$2:$A$4,0))&"","") | E3: =IFERROR(INDEX('Thành viên'!$C$2:$C$4,MATCH(C3,'Thành viên'!$A$2:$A$4,0))&"","") | F3: Sprint 1 | G3: 46293 | H3: 46299 | I3: P0 Critical | J3: Auth (không có trong TaiLieu) | K3: #32 | L3: Todo
A4: P1-02 | B4: Đăng ký Chủ ngựa & xác thực OTP email | C4: Cặp 1 | D4: =IFERROR(INDEX('Thành viên'!$B$2:$B$4,MATCH(C4,'Thành viên'!$A$2:$A$4,0))&"","") | E4: =IFERROR(INDEX('Thành viên'!$C$2:$C$4,MATCH(C4,'Thành viên'!$A$2:$A$4,0))&"","") | F4: Sprint 1 | G4: 46293 | H4: 46299 | I4: P0 Critical | J4: Auth (không có trong TaiLieu) | K4: #33 | L4: Todo
A5: P1-03 | B5: Quên & đặt lại mật khẩu | C5: Cặp 1 | D5: =IFERROR(INDEX('Thành viên'!$B$2:$B$4,MATCH(C5,'Thành viên'!$A$2:$A$4,0))&"","") | E5: =IFERROR(INDEX('Thành viên'!$C$2:$C$4,MATCH(C5,'Thành viên'!$A$2:$A$4,0))&"","") | F5: Sprint 1 | G5: 46293 | H5: 46299 | I5: P0 Critical | J5: Auth (không có trong TaiLieu) | K5: #34 | L5: Todo
A6: P1-04 | B6: Mời nhân sự nội bộ & danh sách nhân sự | C6: Cặp 1 | D6: =IFERROR(INDEX('Thành viên'!$B$2:$B$4,MATCH(C6,'Thành viên'!$A$2:$A$4,0))&"","") | E6: =IFERROR(INDEX('Thành viên'!$C$2:$C$4,MATCH(C6,'Thành viên'!$A$2:$A$4,0))&"","") | F6: Sprint 1 | G6: 46293 | H6: 46299 | I6: P0 Critical | J6: Auth (không có trong TaiLieu) | K6: #35 | L6: Todo
A7: P1-05 | B7: RBAC 5 vai trò, route guard & cách ly dữ liệu Chủ ngựa | C7: Cặp 1 | D7: =IFERROR(INDEX('Thành viên'!$B$2:$B$4,MATCH(C7,'Thành viên'!$A$2:$A$4,0))&"","") | E7: =IFERROR(INDEX('Thành viên'!$C$2:$C$4,MATCH(C7,'Thành viên'!$A$2:$A$4,0))&"","") | F7: Sprint 1 | G7: 46293 | H7: 46299 | I7: P0 Critical | J7: Auth (không có trong TaiLieu) | K7: #36 | L7: Todo
A8: P1-06 | B8: Nhật ký kiểm toán (Audit trail) | C8: Cặp 1 | D8: =IFERROR(INDEX('Thành viên'!$B$2:$B$4,MATCH(C8,'Thành viên'!$A$2:$A$4,0))&"","") | E8: =IFERROR(INDEX('Thành viên'!$C$2:$C$4,MATCH(C8,'Thành viên'!$A$2:$A$4,0))&"","") | F8: Sprint 1 | G8: 46293 | H8: 46299 | I8: P0 Critical | J8: Auth (không có trong TaiLieu) | K8: #37 | L8: Todo
A9: P1-07 | B9: Danh sách, tạo/sửa, chi tiết hồ sơ ngựa (6 tab) | C9: Cặp 1 | D9: =IFERROR(INDEX('Thành viên'!$B$2:$B$4,MATCH(C9,'Thành viên'!$A$2:$A$4,0))&"","") | E9: =IFERROR(INDEX('Thành viên'!$C$2:$C$4,MATCH(C9,'Thành viên'!$A$2:$A$4,0))&"","") | F9: Sprint 2 | G9: 46300 | H9: 46306 | I9: P1 High | J9: FR-1.01, FR-1.02, FR-1.03, FR-1.04, FR-1.26 | K9: #38 | L9: Todo
A10: P1-08 | B10: Trạng thái ngựa, nhóm y tế, badge/banner Khóa huấn luyện, lịch sử trạng thái | C10: Cặp 1 | D10: =IFERROR(INDEX('Thành viên'!$B$2:$B$4,MATCH(C10,'Thành viên'!$A$2:$A$4,0))&"","") | E10: =IFERROR(INDEX('Thành viên'!$C$2:$C$4,MATCH(C10,'Thành viên'!$A$2:$A$4,0))&"","") | F10: Sprint 2 | G10: 46300 | H10: 46306 | I10: P0 Critical | J10: FR-1.05, FR-1.06, FR-1.07, FR-1.17 | K10: #39 | L10: Todo
A11: P1-09 | B11: Sơ đồ chuồng trại, gán/chuyển/trả ô, danh mục khu & ô chuồng | C11: Cặp 1 | D11: =IFERROR(INDEX('Thành viên'!$B$2:$B$4,MATCH(C11,'Thành viên'!$A$2:$A$4,0))&"","") | E11: =IFERROR(INDEX('Thành viên'!$C$2:$C$4,MATCH(C11,'Thành viên'!$A$2:$A$4,0))&"","") | F11: Sprint 2 | G11: 46300 | H11: 46306 | I11: P1 High | J11: FR-1.09, FR-1.10, FR-1.11, FR-1.12, FR-1.18, FR-1.24 | K11: #40 | L11: Todo
A12: P1-10 | B12: Nhân viên chăm sóc, lịch sinh hoạt hằng ngày & lịch mẫu | C12: Cặp 1 | D12: =IFERROR(INDEX('Thành viên'!$B$2:$B$4,MATCH(C12,'Thành viên'!$A$2:$A$4,0))&"","") | E12: =IFERROR(INDEX('Thành viên'!$C$2:$C$4,MATCH(C12,'Thành viên'!$A$2:$A$4,0))&"","") | F12: Sprint 3 | G12: 46307 | H12: 46313 | I12: P1 High | J12: FR-1.13, FR-1.14, FR-1.15, FR-1.25 | K12: #41 | L12: Todo
A13: P1-11 | B13: Chủ sở hữu, ngừng quản lý/kích hoạt lại, xóa mềm & khôi phục | C13: Cặp 1 | D13: =IFERROR(INDEX('Thành viên'!$B$2:$B$4,MATCH(C13,'Thành viên'!$A$2:$A$4,0))&"","") | E13: =IFERROR(INDEX('Thành viên'!$C$2:$C$4,MATCH(C13,'Thành viên'!$A$2:$A$4,0))&"","") | F13: Sprint 3 | G13: 46307 | H13: 46313 | I13: P3 Low | J13: FR-1.08, FR-1.16, FR-1.20, FR-1.21 | K13: #42 | L13: Todo
... A26: C-03 | B26: Nghiệm thu toàn trình MVP-QA | C26: Chung | D26: =IFERROR(INDEX('Thành viên'!$B$2:$B$4,MATCH(C26,'Thành viên'!$A$2:$A$4,0))&"","") | E26: =IFERROR(INDEX('Thành viên'!$C$2:$C$4,MATCH(C26,'Thành viên'!$A$2:$A$4,0))&"","") | F26: Sprint 3 | G26: 46307 | H26: 46313 | I26: P1 High | J26: Toàn bộ Flow 1–3 | K26: #55 | L26: Todo

Sheet Chi tiết theo luồng
A1: Mã | B1: Task | C1: Cặp | D1: Sprint | E1: Luồng | F1: Tên luồng | G1: Bên | H1: Việc cần làm | I1: Người phụ trách | J1: Bắt đầu | K1: Kết thúc | L1: Trạng thái | M1: Issue
A2: C-01 | B2: Nền tảng FE: design tokens, Master layout & routing | C2: Chung | D2: Sprint 1 | E2: NT | F2: Nền tảng giao diện | G2: FE | H2: • Design tokens (Forest Green #315D4B, Manrope/DM Sans), sáng/tối • Layout: AppShell, Sidebar 224px, Topbar 64px, AuthLayout • UI dùng chung: Button, Modal, Toast, Table, Badge, form… • API client + mock (VITE_USE_MOCK), router + RoleGuard | I2: =IFERROR(INDEX('Thành viên'!$B$2:$B$4,MATCH(C2,'Thành viên'!$A$2:$A$4,0))&"","") | J2: 46293 | K2: 46299 | L2: Todo | M2: #31
A3: P1-01 | B3: Đăng nhập, JWT & điều hướng 5 vai trò | C3: Cặp 1 | D3: Sprint 1 | E3: WF1-1 | F3: Luồng chính: đăng nhập thành công → dashboard theo vai trò | G3: FE | H3: • Màn Login (AUTH01): email → mật khẩu, "Remember me" • Lưu token, điều hướng theo vai trò | I3: =IFERROR(INDEX('Thành viên'!$B$2:$B$4,MATCH(C3,'Thành viên'!$A$2:$A$4,0))&"","") | J3: 46293 | K3: 46294 | L3: Todo | M3: #32
A4: P1-01 | B4: Đăng nhập, JWT & điều hướng 5 vai trò | C4: Cặp 1 | D4: Sprint 1 | E4: WF1-1 | F4: Luồng chính: đăng nhập thành công → dashboard theo vai trò | G4: BE | H4: • POST /auth/login: kiểm tra mật khẩu, cấp access 15 phút + refresh 7 ngày (30 ngày khi remember) • GET /auth/me trả hồ sơ + quyền | I4: =IFERROR(INDEX('Thành viên'!$C$2:$C$4,MATCH(C4,'Thành viên'!$A$2:$A$4,0))&"","") | J4: 46293 | K4: 46294 | L4: Todo | M4: #32
A5: P1-01 | B5: Đăng nhập, JWT & điều hướng 5 vai trò | C5: Cặp 1 | D5: Sprint 1 | E5: WF1-2 | F5: Rẽ nhánh: 8 trường hợp bị chặn (khóa, chờ duyệt, chưa xác minh…) | G5: FE | H5: • Hiện đúng thông báo theo code: ACCOUNT_LOCKED, ACCOUNT_PENDING, EMAIL_NOT_VERIFIED… | I5: =IFERROR(INDEX('Thành viên'!$B$2:$B$4,MATCH(C5,'Thành viên'!$A$2:$A$4,0))&"","") | J5: 46293 | K5: 46294 | L5: Todo | M5: #32
A6: P1-01 | B6: Đăng nhập, JWT & điều hướng 5 vai trò | C6: Cặp 1 | D6: Sprint 1 | E6: WF1-2 | F6: Rẽ nhánh: 8 trường hợp bị chặn (khóa, chờ duyệt, chưa xác minh…) | G6: BE | H6: • Trả 423/403 kèm code + data (fullName, requestCode, reason…) | I6: =IFERROR(INDEX('Thành viên'!$C$2:$C$4,MATCH(C6,'Thành viên'!$A$2:$A$4,0))&"","") | J6: 46293 | K6: 46294 | L6: Todo | M6: #32
A7: P1-01 | B7: Đăng nhập, JWT & điều hướng 5 vai trò | C7: Cặp 1 | D7: Sprint 1 | E7: WF1-3 | F7: Khóa tạm sau 5 lần sai | G7: FE | H7: • Hiện số lần còn lại, đếm ngược tới retryAt | I7: =IFERROR(INDEX('Thành viên'!$B$2:$B$4,MATCH(C7,'Thành viên'!$A$2:$A$4,0))&"","") | J7: 46293 | K7: 46294 | L7: Todo | M7: #32
A8: P1-01 | B8: Đăng nhập, JWT & điều hướng 5 vai trò | C8: Cặp 1 | D8: Sprint 1 | E8: WF1-3 | F8: Khóa tạm sau 5 lần sai | G8: BE | H8: • LoginAttempt: sai 5 lần khóa 15 phút (429 ATTEMPTS_EXCEEDED) | I8: =IFERROR(INDEX('Thành viên'!$C$2:$C$4,MATCH(C8,'Thành viên'!$A$2:$A$4,0))&"","") | J8: 46293 | K8: 46294 | L8: Todo | M8: #32
A9: P1-01 | B9: Đăng nhập, JWT & điều hướng 5 vai trò | C9: Cặp 1 | D9: Sprint 1 | E9: WF1-4/5/6 | F9: Khôi phục phiên, hết phiên, đăng xuất | G9: FE | H9: • Tải lại trang giữ đăng nhập; 401 → tự làm mới token, không được thì modal Session Expired • Đăng xuất xóa token | I9: =IFERROR(INDEX('Thành viên'!$B$2:$B$4,MATCH(C9,'Thành viên'!$A$2:$A$4,0))&"","") | J9: 46293 | K9: 46294 | L9: Todo | M9: #32
A10: P1-01 | B10: Đăng nhập, JWT & điều hướng 5 vai trò | C10: Cặp 1 | D10: Sprint 1 | E10: WF1-4/5/6 | F10: Khôi phục phiên, hết phiên, đăng xuất | G10: BE | H10: • POST /auth/refresh xoay vòng refresh token • POST /auth/logout thu hồi refresh token | I10: =IFERROR(INDEX('Thành viên'!$C$2:$C$4,MATCH(C10,'Thành viên'!$A$2:$A$4,0))&"","") | J10: 46293 | K10: 46294 | L10: Todo | M10: #32
A11: P1-02 | B11: Đăng ký Chủ ngựa & xác thực OTP email | C11: Cặp 1 | D11: Sprint 1 | E11: ĐK-1 | F11: Đăng ký → nhận mã OTP qua email | G11: FE | H11: • Màn Sign Up (AUTH02): họ tên, email @gmail.com, mật khẩu (thang độ mạnh) | I11: =IFERROR(INDEX('Thành viên'!$B$2:$B$4,MATCH(C11,'Thành viên'!$A$2:$A$4,0))&"","") | J11: 46294 | K11: 46295 | L11: Todo | M11: #33
A12: P1-02 | B12: Đăng ký Chủ ngựa & xác thực OTP email | C12: Cặp 1 | D12: Sprint 1 | E12: ĐK-1 | F12: Đăng ký → nhận mã OTP qua email | G12: BE | H12: • POST /auth/register: chỉ HORSE_OWNER, tạo PENDING_EMAIL + requestCode REQ-YYMM-NNN, gửi OTP | I12: =IFERROR(INDEX('Thành viên'!$C$2:$C$4,MATCH(C12,'Thành viên'!$A$2:$A$4,0))&"","") | J12: 46294 | K12: 46295 | L12: Todo | M12: #33
A13: P1-02 | B13: Đăng ký Chủ ngựa & xác thực OTP email | C13: Cặp 1 | D13: Sprint 1 | E13: ĐK-2 | F13: Nhập OTP → chờ duyệt | G13: FE | H13: • Form OTP: đếm ngược hết hạn, gửi lại sau 60 giây, báo số lần còn lại • Màn Pending Approval hiện mã yêu cầu | I13: =IFERROR(INDEX('Thành viên'!$B$2:$B$4,MATCH(C13,'Thành viên'!$A$2:$A$4,0))&"","") | J13: 46294 | K13: 46295 | L13: Todo | M13: #33
A14: P1-02 | B14: Đăng ký Chủ ngựa & xác thực OTP email | C14: Cặp 1 | D14: Sprint 1 | E14: ĐK-2 | F14: Nhập OTP → chờ duyệt | G14: BE | H14: • POST /auth/verify-email → PENDING_APPROVAL • GET /auth/otp, POST /auth/otp/resend (chờ 60 giây, sai 5 lần khóa mã) | I14: =IFERROR(INDEX('Thành viên'!$C$2:$C$4,MATCH(C14,'Thành viên'!$A$2:$A$4,0))&"","") | J14: 46294 | K14: 46295 | L14: Todo | M14: #33
A15: P1-03 | B15: Quên & đặt lại mật khẩu | C15: Cặp 1 | D15: Sprint 1 | E15: QMK-1 | F15: Nhập email → nhận mã | G15: FE | H15: • Màn Forgot Password (AUTH03): thông báo trung tính | I15: =IFERROR(INDEX('Thành viên'!$B$2:$B$4,MATCH(C15,'Thành viên'!$A$2:$A$4,0))&"","") | J15: 46295 | K15: 46296 | L15: Todo | M15: #34
A16: P1-03 | B16: Quên & đặt lại mật khẩu | C16: Cặp 1 | D16: Sprint 1 | E16: QMK-1 | F16: Nhập email → nhận mã | G16: BE | H16: • POST /auth/forgot-password: trả giống nhau dù email có tồn tại hay không | I16: =IFERROR(INDEX('Thành viên'!$C$2:$C$4,MATCH(C16,'Thành viên'!$A$2:$A$4,0))&"","") | J16: 46295 | K16: 46296 | L16: Todo | M16: #34
A17: P1-03 | B17: Quên & đặt lại mật khẩu | C17: Cặp 1 | D17: Sprint 1 | E17: QMK-2 | F17: Nhập mã → đặt mật khẩu mới | G17: FE | H17: • Màn Reset Password (AUTH04): OTP + mật khẩu mới | I17: =IFERROR(INDEX('Thành viên'!$B$2:$B$4,MATCH(C17,'Thành viên'!$A$2:$A$4,0))&"","") | J17: 46295 | K17: 46296 | L17: Todo | M17: #34
A18: P1-03 | B18: Quên & đặt lại mật khẩu | C18: Cặp 1 | D18: Sprint 1 | E18: QMK-2 | F18: Nhập mã → đặt mật khẩu mới | G18: BE | H18: • POST /auth/reset-password/verify → vé đặt mật khẩu • POST /auth/reset-password: vé dùng 1 lần, thu hồi mọi phiên cũ | I18: =IFERROR(INDEX('Thành viên'!$C$2:$C$4,MATCH(C18,'Thành viên'!$A$2:$A$4,0))&"","") | J18: 46295 | K18: 46296 | L18: Todo | M18: #34
A19: P1-04 | B19: Mời nhân sự nội bộ & danh sách nhân sự | C19: Cặp 1 | D19: Sprint 1 | E19: TK-1 | F19: Mời nhân sự → nhận lời mời → đặt mật khẩu | G19: FE | H19: • Modal mời (SYS02): họ tên, email, vai trò • Màn Accept Invite: email + mã mời → đặt mật khẩu | I19: =IFERROR(INDEX('Thành viên'!$B$2:$B$4,MATCH(C19,'Thành viên'!$A$2:$A$4,0))&"","") | J19: 46296 | K19: 46297 | L19: Todo | M19: #35
A20: P1-04 | B20: Mời nhân sự nội bộ & danh sách nhân sự | C20: Cặp 1 | D20: Sprint 1 | E20: TK-1 | F20: Mời nhân sự → nhận lời mời → đặt mật khẩu | G20: BE | H20: • POST /accounts: tạo INVITED + gửi mã mời 48 giờ • POST /auth/accept-invite/verify; POST /accounts/:id/resend-invite | I20: =IFERROR(INDEX('Thành viên'!$C$2:$C$4,MATCH(C20,'Thành viên'!$A$2:$A$4,0))&"","") | J20: 46296 | K20: 46297 | L20: Todo | M20: #35
A21: P1-04 | B21: Mời nhân sự nội bộ & danh sách nhân sự | C21: Cặp 1 | D21: Sprint 1 | E21: TK-2 | F21: Duyệt / từ chối / khóa / mở khóa / vô hiệu hóa / kích hoạt lại / xóa | G21: FE | H21: • Danh sách tài khoản (SYS01) theo tab trạng thái • Hộp thoại nhập lý do, sửa họ tên + SĐT | I21: =IFERROR(INDEX('Thành viên'!$B$2:$B$4,MATCH(C21,'Thành viên'!$A$2:$A$4,0))&"","") | J21: 46296 | K21: 46297 | L21: Todo | M21: #35
A22: P1-04 | B22: Mời nhân sự nội bộ & danh sách nhân sự | C22: Cặp 1 | D22: Sprint 1 | E22: TK-2 | F22: Duyệt / từ chối / khóa / mở khóa / vô hiệu hóa / kích hoạt lại / xóa | G22: BE | H22: • POST /accounts/:id/{approve,decline,lock,unlock,deactivate,reactivate} • PUT /accounts/:id; DELETE /accounts/:id (chỉ tài khoản chưa dùng) • Không tự khóa mình; luôn còn ≥ 1 Club Manager | I22: =IFERROR(INDEX('Thành viên'!$C$2:$C$4,MATCH(C22,'Thành viên'!$A$2:$A$4,0))&"","") | J22: 46296 | K22: 46297 | L22: Todo | M22: #35
A23: P1-05 | B23: RBAC 5 vai trò, route guard & cách ly dữ liệu Chủ ngựa | C23: Cặp 1 | D23: Sprint 1 | E23: PQ-1 | F23: Chặn theo quyền + trang 403 | G23: FE | H23: • RoleGuard, sidebar theo quyền, trang 403 + mã tham chiếu | I23: =IFERROR(INDEX('Thành viên'!$B$2:$B$4,MATCH(C23,'Thành viên'!$A$2:$A$4,0))&"","") | J23: 46297 | K23: 46298 | L23: Todo | M23: #36
A24: P1-05 | B24: RBAC 5 vai trò, route guard & cách ly dữ liệu Chủ ngựa | C24: Cặp 1 | D24: Sprint 1 | E24: PQ-1 | F24: Chặn theo quyền + trang 403 | G24: BE | H24: • PermissionsGuard + @RequirePermission; mọi API tự kiểm tra quyền (không chỉ ẩn nút) • POST /audit/forbidden | I24: =IFERROR(INDEX('Thành viên'!$C$2:$C$4,MATCH(C24,'Thành viên'!$A$2:$A$4,0))&"","") | J24: 46297 | K24: 46298 | L24: Todo | M24: #36
A25: P1-05 | B25: RBAC 5 vai trò, route guard & cách ly dữ liệu Chủ ngựa | C25: Cặp 1 | D25: Sprint 1 | E25: PQ-2 | F25: Bật/tắt quyền, xin cấp quyền | G25: FE | H25: • Ma trận quyền (Permissions), hộp yêu cầu cấp quyền của Manager | I25: =IFERROR(INDEX('Thành viên'!$B$2:$B$4,MATCH(C25,'Thành viên'!$A$2:$A$4,0))&"","") | J25: 46297 | K25: 46298 | L25: Todo | M25: #36
A26: P1-05 | B26: RBAC 5 vai trò, route guard & cách ly dữ liệu Chủ ngựa | C26: Cặp 1 | D26: Sprint 1 | E26: PQ-2 | F26: Bật/tắt quyền, xin cấp quyền | G26: BE | H26: • PUT /accounts/:id/permissions (ép các quyền khóa theo vai trò) • POST/GET /permission-requests, POST /permission-requests/:id/resolve | I26: =IFERROR(INDEX('Thành viên'!$C$2:$C$4,MATCH(C26,'Thành viên'!$A$2:$A$4,0))&"","") | J26: 46297 | K26: 46298 | L26: Todo | M26: #36
A27: P1-05 | B27: RBAC 5 vai trò, route guard & cách ly dữ liệu Chủ ngựa | C27: Cặp 1 | D27: Sprint 1 | E27: PQ-3 | F27: Cách ly dữ liệu Chủ ngựa | G27: FE | H27: • Owner chỉ thấy ngựa của mình | I27: =IFERROR(INDEX('Thành viên'!$B$2:$B$4,MATCH(C27,'Thành viên'!$A$2:$A$4,0))&"","") | J27: 46297 | K27: 46298 | L27: Todo | M27: #36
A28: P1-05 | B28: RBAC 5 vai trò, route guard & cách ly dữ liệu Chủ ngựa | C28: Cặp 1 | D28: Sprint 1 | E28: PQ-3 | F28: Cách ly dữ liệu Chủ ngựa | G28: BE | H28: • Owner A gọi dữ liệu ngựa của Owner B → 403 (áp dụng cho mọi API ngựa, y tế, huấn luyện) | I28: =IFERROR(INDEX('Thành viên'!$C$2:$C$4,MATCH(C28,'Thành viên'!$A$2:$A$4,0))&"","") | J28: 46297 | K28: 46298 | L28: Todo | M28: #36
A29: P1-06 | B29: Nhật ký kiểm toán (Audit trail) | C29: Cặp 1 | D29: Sprint 1 | E29: NK-1 | F29: Ghi nhật ký tự động | G29: BE | H29: • Mọi thao tác ghi (khóa, đổi quyền, đặt/gỡ khóa huấn luyện…) ghi AuditLog; không có API sửa/xóa log | I29: =IFERROR(INDEX('Thành viên'!$C$2:$C$4,MATCH(C29,'Thành viên'!$A$2:$A$4,0))&"","") | J29: 46298 | K29: 46299 | L29: Todo | M29: #37
A30: P1-06 | B30: Nhật ký kiểm toán (Audit trail) | C30: Cặp 1 | D30: Sprint 1 | E30: NK-2 | F30: Xem và lọc nhật ký (Manager) | G30: FE | H30: • Màn Audit Log: lọc theo người, hành động, khoảng ngày; phân trang | I30: =IFERROR(INDEX('Thành viên'!$B$2:$B$4,MATCH(C30,'Thành viên'!$A$2:$A$4,0))&"","") | J30: 46298 | K30: 46299 | L30: Todo | M30: #37
A31: P1-06 | B31: Nhật ký kiểm toán (Audit trail) | C31: Cặp 1 | D31: Sprint 1 | E31: NK-2 | F31: Xem và lọc nhật ký (Manager) | G31: BE | H31: • GET /audit-logs (API-017) có lọc + phân trang, chỉ người có quyền viewAudit | I31: =IFERROR(INDEX('Thành viên'!$C$2:$C$4,MATCH(C31,'Thành viên'!$A$2:$A$4,0))&"","") | J31: 46298 | K31: 46299 | L31: Todo | M31: #37
A32: P1-07 | B32: Danh sách, tạo/sửa, chi tiết hồ sơ ngựa (6 tab) | C32: Cặp 1 | D32: Sprint 2 | E32: F1-L1 | F32: Tạo ngựa (bước 1–2): Thêm ngựa → nhập định danh → Lưu | G32: FE | H32: • SC-1.02 form 8 ô: Tên, Giống, Ngày sinh, Giới tính, Màu lông, Microchip, RFID • Cảnh báo rời form chưa lưu (DL-1.12) | I32: =IFERROR(INDEX('Thành viên'!$B$2:$B$4,MATCH(C32,'Thành viên'!$A$2:$A$4,0))&"","") | J32: 46300 | K32: 46302 | L32: Todo | M32: #38
A33: P1-07 | B33: Danh sách, tạo/sửa, chi tiết hồ sơ ngựa (6 tab) | C33: Cặp 1 | D33: Sprint 2 | E33: F1-L1 | F33: Tạo ngựa (bước 1–2): Thêm ngựa → nhập định danh → Lưu | G33: BE | H33: • POST /horses: tự sinh Mã ngựa, trạng thái đầu Nghỉ ngơi, chặn trùng Tên/Microchip/RFID • PUT /horses/:id sửa định danh | I33: =IFERROR(INDEX('Thành viên'!$C$2:$C$4,MATCH(C33,'Thành viên'!$A$2:$A$4,0))&"","") | J33: 46300 | K33: 46302 | L33: Todo | M33: #38
A34: P1-07 | B34: Danh sách, tạo/sửa, chi tiết hồ sơ ngựa (6 tab) | C34: Cặp 1 | D34: Sprint 2 | E34: F1-L8 | F34: Tra cứu: danh sách + chi tiết | G34: FE | H34: • SC-1.01 danh sách: 7 bộ lọc, sắp xếp, phân trang • SC-1.03 chi tiết: header + tab Thông tin; che Microchip với GROOM | I34: =IFERROR(INDEX('Thành viên'!$B$2:$B$4,MATCH(C34,'Thành viên'!$A$2:$A$4,0))&"","") | J34: 46300 | K34: 46302 | L34: Todo | M34: #38
A35: P1-07 | B35: Danh sách, tạo/sửa, chi tiết hồ sơ ngựa (6 tab) | C35: Cặp 1 | D35: Sprint 2 | E35: F1-L8 | F35: Tra cứu: danh sách + chi tiết | G35: BE | H35: • GET /horses theo phạm vi vai trò (Owner chỉ ngựa của mình) • GET /horses/:id (ẩn microchip với GROOM) | I35: =IFERROR(INDEX('Thành viên'!$C$2:$C$4,MATCH(C35,'Thành viên'!$A$2:$A$4,0))&"","") | J35: 46300 | K35: 46302 | L35: Todo | M35: #38
A36: P1-08 | B36: Trạng thái ngựa, nhóm y tế, badge/banner Khóa huấn luyện, lịch sử trạng thái | C36: Cặp 1 | D36: Sprint 2 | E36: F1-L2 | F36: HT đổi trạng thái vận hành | G36: FE | H36: • DL-1.01: chỉ hiện trạng thái vai trò được chuyển tới | I36: =IFERROR(INDEX('Thành viên'!$B$2:$B$4,MATCH(C36,'Thành viên'!$A$2:$A$4,0))&"","") | J36: 46302 | K36: 46304 | L36: Todo | M36: #39
A37: P1-08 | B37: Trạng thái ngựa, nhóm y tế, badge/banner Khóa huấn luyện, lịch sử trạng thái | C37: Cặp 1 | D37: Sprint 2 | E37: F1-L2 | F37: HT đổi trạng thái vận hành | G37: BE | H37: • API đổi trạng thái theo bảng chuyển Mục 4.2 | I37: =IFERROR(INDEX('Thành viên'!$C$2:$C$4,MATCH(C37,'Thành viên'!$A$2:$A$4,0))&"","") | J37: 46302 | K37: 46304 | L37: Todo | M37: #39
A38: P1-08 | B38: Trạng thái ngựa, nhóm y tế, badge/banner Khóa huấn luyện, lịch sử trạng thái | C38: Cặp 1 | D38: Sprint 2 | E38: F1-L3 | F38: VET đổi trạng thái y tế (lý do bắt buộc) | G38: FE | H38: • DL-1.01 với lý do 10–500 ký tự, khung gợi ý đặt khóa | I38: =IFERROR(INDEX('Thành viên'!$B$2:$B$4,MATCH(C38,'Thành viên'!$A$2:$A$4,0))&"","") | J38: 46302 | K38: 46304 | L38: Todo | M38: #39
A39: P1-08 | B39: Trạng thái ngựa, nhóm y tế, badge/banner Khóa huấn luyện, lịch sử trạng thái | C39: Cặp 1 | D39: Sprint 2 | E39: F1-L3 | F39: VET đổi trạng thái y tế (lý do bắt buộc) | G39: BE | H39: • Chỉ VET vào/ra nhóm y tế; lý do bắt buộc | I39: =IFERROR(INDEX('Thành viên'!$C$2:$C$4,MATCH(C39,'Thành viên'!$A$2:$A$4,0))&"","") | J39: 46302 | K39: 46304 | L39: Todo | M39: #39
A40: P1-08 | B40: Trạng thái ngựa, nhóm y tế, badge/banner Khóa huấn luyện, lịch sử trạng thái | C40: Cặp 1 | D40: Sprint 2 | E40: F1-L4 | F40: Nhận Khóa huấn luyện từ Flow 3 | G40: FE | H40: • Badge + banner đỏ, vô hiệu hóa nút theo Mục 4.2, bộ lọc Khóa huấn luyện | I40: =IFERROR(INDEX('Thành viên'!$B$2:$B$4,MATCH(C40,'Thành viên'!$A$2:$A$4,0))&"","") | J40: 46302 | K40: 46304 | L40: Todo | M40: #39
...

Sheet Tổng quan
A1: Sprint | B1: Cặp | C1: Số task | D1: Done | E1: Tiến độ
A2: Sprint 1 | B2: Cặp 1 | C2: =COUNTIFS('Phân công'!$F$2:$F$26,A2,'Phân công'!$C$2:$C$26,B2) | D2: =COUNTIFS('Phân công'!$F$2:$F$26,A2,'Phân công'!$C$2:$C$26,B2,'Phân công'!$L$2:$L$26,"Done") | E2: =IF(C2=0,"-",D2/C2)
A3: Sprint 1 | B3: Cặp 2 | C3: =COUNTIFS('Phân công'!$F$2:$F$26,A3,'Phân công'!$C$2:$C$26,B3) | D3: =COUNTIFS('Phân công'!$F$2:$F$26,A3,'Phân công'!$C$2:$C$26,B3,'Phân công'!$L$2:$L$26,"Done") | E3: =IF(C3=0,"-",D3/C3)
A4: Sprint 1 | B4: Chung | C4: =COUNTIFS('Phân công'!$F$2:$F$26,A4,'Phân công'!$C$2:$C$26,B4) | D4: =COUNTIFS('Phân công'!$F$2:$F$26,A4,'Phân công'!$C$2:$C$26,B4,'Phân công'!$L$2:$L$26,"Done") | E4: =IF(C4=0,"-",D4/C4)
A5: Sprint 2 | B5: Cặp 1 | C5: =COUNTIFS('Phân công'!$F$2:$F$26,A5,'Phân công'!$C$2:$C$26,B5) | D5: =COUNTIFS('Phân công'!$F$2:$F$26,A5,'Phân công'!$C$2:$C$26,B5,'Phân công'!$L$2:$L$26,"Done") | E5: =IF(C5=0,"-",D5/C5)
A6: Sprint 2 | B6: Cặp 2 | C6: =COUNTIFS('Phân công'!$F$2:$F$26,A6,'Phân công'!$C$2:$C$26,B6) | D6: =COUNTIFS('Phân công'!$F$2:$F$26,A6,'Phân công'!$C$2:$C$26,B6,'Phân công'!$L$2:$L$26,"Done") | E6: =IF(C6=0,"-",D6/C6)
A7: Sprint 2 | B7: Chung | C7: =COUNTIFS('Phân công'!$F$2:$F$26,A7,'Phân công'!$C$2:$C$26,B7) | D7: =COUNTIFS('Phân công'!$F$2:$F$26,A7,'Phân công'!$C$2:$C$26,B7,'Phân công'!$L$2:$L$26,"Done") | E7: =IF(C7=0,"-",D7/C7)
A8: Sprint 3 | B8: Cặp 1 | C8: =COUNTIFS('Phân công'!$F$2:$F$26,A8,'Phân công'!$C$2:$C$26,B8) | D8: =COUNTIFS('Phân công'!$F$2:$F$26,A8,'Phân công'!$C$2:$C$26,B8,'Phân công'!$L$2:$L$26,"Done") | E8: =IF(C8=0,"-",D8/C8)
A9: Sprint 3 | B9: Cặp 2 | C9: =COUNTIFS('Phân công'!$F$2:$F$26,A9,'Phân công'!$C$2:$C$26,B9) | D9: =COUNTIFS('Phân công'!$F$2:$F$26,A9,'Phân công'!$C$2:$C$26,B9,'Phân công'!$L$2:$L$26,"Done") | E9: =IF(C9=0,"-",D9/C9)
A10: Sprint 3 | B10: Chung | C10: =COUNTIFS('Phân công'!$F$2:$F$26,A10,'Phân công'!$C$2:$C$26,B10) | D10: =COUNTIFS('Phân công'!$F$2:$F$26,A10,'Phân công'!$C$2:$C$26,B10,'Phân công'!$L$2:$L$26,"Done") | E10: =IF(C10=0,"-",D10/C10)
A11: Tổng | C11: =SUM(C2:C10) | D11: =SUM(D2:D10) | E11: =IF(C11=0,"-",D11/C11)

Sheet Thành viên
A1: Cặp | B1: Frontend | C1: Backend
A2: Cặp 1
A3: Cặp 2
A4: Chung | B4: Cả 2 FE | C4: Cả 2 BE
A6: Hướng dẫn: điền tên (hoặc GitHub username) vào các ô vàng. Sheet "Phân công" tự lấy tên theo cặp.

Sheet Điểm nối
A1: Cặp cung cấp | B1: Cặp dùng | C1: Nội dung cần thống nhất API
A2: Cặp 1 (P1-05) | B2: Cặp 2 | C2: Đăng nhập, vai trò, cách ly dữ liệu Owner — mọi API của Cặp 2 dùng chung guard
A3: Cặp 1 (P1-07, P1-09, P1-10) | B3: Cặp 2 | C3: Danh sách ngựa, trạng thái, ô chuồng, nhân viên chăm sóc phụ trách
A4: Cặp 2 (P2-04) | B4: Cặp 1 (P1-08, P1-14) | C4: Đặt/gỡ Khóa huấn luyện → đổi trạng thái ngựa, bật/tắt banner, màu trên sơ đồ sức khỏe
A5: Cặp 2 (P2-02, P2-06 → P2-09) | B5: Cặp 1 (P1-13) | C5: Sự kiện y tế & huấn luyện cho dòng thời gian ngựa
